<?xml version="1.0" encoding="utf-8"?>
<robot name="dvrk_psm" xmlns:xacro="http://www.ros.org/wiki/xacro">
  <!-- Colors -->
  <xacro:include filename="$(find dvrk_model)/model/common.urdf.xacro"/>

  <xacro:macro name="psm" params="prefix parent_link xyz rpy">
    <!-- fixed joint -->
    <joint name="${prefix}fixed_joint" type="fixed">
      <parent link="${parent_link}"/>
      <child link="${prefix}remote_center_link"/>
      <origin rpy="${rpy}" xyz="${xyz}"/>
    </joint>

    <!-- link rc: remote centre link -->
    <link name="${prefix}remote_center_link" />   

    <!-- fixed joint -->
    <joint name="${prefix}rc_fixed_joint" type="fixed">
      <parent link="${prefix}remote_center_link"/>
      <child link="${prefix}psm_base_link"/>
      <origin rpy="0 0 0" xyz="0 -0.369 0"/>
    </joint>

    <!-- link 0: psm base link -->
    <link name="${prefix}psm_base_link">
      <visual>
        <origin rpy="1.5708 0 3.1416" xyz="0.039 -0.03888 -0.07879"/>
        <geometry>
          <mesh filename="package://dvrk_model/meshes/psm/psm_base.dae"/>      
        </geometry>
      </visual>
      <inertial>
        <mass value="1"/>
        <inertia ixx="1.0" ixy="0.0" ixz="0.0" iyy="1.0" iyz="0.0" izz="1.0"/>
      </inertial>
    </link>
    
    <!-- joint 1 -->
    <joint name="${prefix}outer_yaw_joint" type="revolute">
      <parent link="${prefix}psm_base_link"/>
      <child link="${prefix}outer_yaw_link"/>
      <axis xyz="0 0 1"/>
      <origin rpy="1.5708 -1.5708 0" xyz="0.0 0.0 0.0"/>
      <limit lower="-1.5707" upper="1.5707" velocity=".4" effort="1000"/>
    </joint> 
    
    
    <!-- link 1: outer_yaw / shoulder-->
    <link name="${prefix}outer_yaw_link">
      <visual>
        <!-- <origin rpy="0 0 -1.5708" xyz="0.0125 0 0.1575"/> -->
        <origin rpy="3.1416 0 1.5708" xyz="0.0125 0 0.1575"/>
        <geometry>
          <mesh filename="package://dvrk_model/meshes/psm/outer_yaw.dae"/>      
        </geometry>
      </visual>
      <inertial>
        <mass value="0.660047"/>
        <inertia ixx="0.004657" ixy="0.000004" ixz="0.000003" iyy="0.006417" iyz="0.000302" izz="0.003642"/>
      </inertial>
    </link>

    <!-- joint 2-1: outer_pitch_1 -->
    <joint name="${prefix}outer_pitch_joint_1" type="revolute">
      <parent link="${prefix}outer_yaw_link"/>
      <child link="${prefix}outer_pitch_back_link"/>
      <axis xyz="0 0 1"/>
      <origin rpy="-1.5708 -1.5708 0" xyz="0 0.0295 0.1495"/>
      <limit lower="-0.7854" upper="0.7854" velocity=".4" effort="1000"/>
    </joint> 
    
    <!-- link 2: outer_pitch_back /elbow -->
    <link name="${prefix}outer_pitch_back_link">
      <visual>
        <origin rpy="0 0 -0.27129" xyz="0 0 0"/>
        <geometry>
          <mesh filename="package://dvrk_model/meshes/psm/outer_pitch_back.dae"/>      
        </geometry>
      </visual>
      <inertial>
        <mass value="0.038460"/>
        <inertia ixx="0.000153" ixy="0.000001" ixz="0.0" iyy="0.000022" iyz="-0.000051" izz="0.000132"/>
      </inertial>
    </link>

    <!-- joint 2-2: outer_pitch_2 -->
    <joint name="${prefix}outer_pitch_joint_2" type="continuous">
      <parent link="${prefix}outer_yaw_link"/>
      <child link="${prefix}outer_pitch_front_link"/>
      <axis xyz="0 0 1"/>
      <origin rpy="-1.5708 -1.5708 0" xyz="0 0.0295 0.0595"/>
      <mimic joint="${prefix}outer_pitch_joint_1" multiplier="1"/>
    </joint>

    <!-- link 2-2: outer_pitch_front -->
    <link name="${prefix}outer_pitch_front_link">
      <visual>
        <origin rpy="0 0 -0.27129" xyz="0 0 0"/>
        <!-- <origin rpy="0 0 0" xyz="0 0 0"/> -->
        <geometry>
          <mesh filename="package://dvrk_model/meshes/psm/outer_pitch_front.dae"/>      
        </geometry>
      </visual>
      <inertial>
        <mass value="1"/>
        <inertia ixx="1.0" ixy="0.0" ixz="0.0" iyy="1.0" iyz="0.0" izz="1.0"/>
      </inertial>
    </link>

    <!-- joint 2-3: outer_pitch_3 -->
    <joint name="${prefix}outer_pitch_joint_3" type="continuous">
      <parent link="${prefix}outer_pitch_back_link"/>
      <child link="${prefix}outer_pitch_bottom_link"/>
      <axis xyz="0 0 1"/>
      <origin rpy="0 0 0" xyz="0.04178 0.15007 -0.0137"/>
      <mimic joint="${prefix}outer_pitch_joint_1" multiplier="-1"/>
    </joint>

    <!-- link 2-3: outer_pitch_bottom -->
    <link name="${prefix}outer_pitch_bottom_link">
      <visual>
        <origin rpy="0 -1.5708 0" xyz="0.009 0 0"/>
        <geometry>
          <mesh filename="package://dvrk_model/meshes/psm/outer_pitch_bottom.dae"/>      
        </geometry>
      </visual>
      <inertial>
        <mass value="1"/>
        <inertia ixx="1.0" ixy="0.0" ixz="0.0" iyy="1.0" iyz="0.0" izz="1.0"/>
      </inertial>
    </link>

    <!-- joint 2-4: outer_pitch_4 -->
    <joint name="${prefix}outer_pitch_joint_4" type="continuous">
      <parent link="${prefix}outer_pitch_back_link"/>
      <child link="${prefix}outer_pitch_top_link"/>
      <axis xyz="0 0 1"/>
      <origin rpy="0 0 0" xyz="0.04209 0.18695 -0.02412"/>
      <mimic joint="${prefix}outer_pitch_joint_1" multiplier="-1"/>
    </joint>

    <!-- link 2-4: outer_pitch_top /forearm -->
    <link name="${prefix}outer_pitch_top_link">
      <visual>
        <origin rpy="0 -1.5708 0" xyz="0.009 0 0"/>
        <geometry>
          <mesh filename="package://dvrk_model/meshes/psm/outer_pitch_top.dae"/>      
        </geometry>
      </visual>
      <inertial>
        <mass value="0.151565"/>
        <inertia ixx="0.003345" ixy="0.0" ixz="0.0" iyy="0.003401" iyz="0.0" izz="0.000064"/>
      </inertial>
    </link>

    <!-- joint 2-5: outer_pitch_5 -->
    <joint name="${prefix}outer_pitch_joint_5" type="continuous">
      <parent link="${prefix}outer_pitch_bottom_link"/>
      <child link="${prefix}outer_insertion_link"/>
      <axis xyz="0 0 1"/>
      <origin rpy="0 0 0" xyz="-0.520 0 -0.0155"/>
      <mimic joint="${prefix}outer_pitch_joint_1" multiplier="1"/>
    </joint>

    <!-- link 2-5: outer_insertion / wrist -->
    <link name="${prefix}outer_insertion_link">
      <visual>
        <origin rpy="0 -1.5708 1.5708" xyz="0.02528 0.429 0"/>
        <geometry>
          <mesh filename="package://dvrk_model/meshes/psm/outer_insertion.dae"/>      
        </geometry>
      </visual>
      <inertial>
        <mass value="1.209778"/>
        <inertia ixx="0.025675" ixy="0.0" ixz="0.0" iyy="0.001345" iyz="-0.003795" izz="0.025537"/>
      </inertial>
    </link>

    <!-- joint 3: insertion -->
    <joint name="${prefix}outer_insertion_joint" type="prismatic">
      <parent link="${prefix}outer_insertion_link"/>
      <child link="${prefix}tool_main_link"/>
      <axis xyz="0 0 1"/>
      <origin rpy="1.5708 0 0" xyz="-0.0403 0.23622 0"/>
      <limit lower="0" upper="0.240" velocity=".4" effort="1000"/>
    </joint>

    <!-- link 3: tool_main_link / hand -->
    <link name="${prefix}tool_main_link">
      <visual>
        <origin rpy="0 0 1.5708" xyz="0 0 0"/>
        <geometry>
          <mesh filename="package://dvrk_model/meshes/psm/tool_main.dae"/>      
        </geometry>
      </visual>
      <inertial>
        <mass value="0.244362"/>
        <inertia ixx="0.001436" ixy="-0.000001" ixz="0.0" iyy="0.000136" iyz="-0.000220" izz="0.001437"/>
      </inertial>
    </link>
    
    <!-- joint 4-1: Outer Roll -->
    <joint name="${prefix}outer_roll_joint" type="revolute">
      <parent link="${prefix}tool_main_link"/>
      <child link="${prefix}tool_wrist_link"/>
      <axis xyz="0 0 1"/>
      <origin rpy="0 0 0" xyz="0 0 0.36680"/>
      <limit lower="-2.2689" upper="2.2689" velocity=".4" effort="1000"/>
    </joint>

    <!-- link 4-1: tool_main_link / finger1 -->
    <link name="${prefix}tool_wrist_link">
      <visual>
        <origin rpy="0 0 1.5708" xyz="0 0 0"/>
        <geometry>
          <mesh filename="package://dvrk_model/meshes/psm/tool_wrist_link.dae"/>      
        </geometry>
      </visual>
      <inertial>
        <mass value="0.000332"/>
        <inertia ixx="0.0" ixy="0.0" ixz="0.0" iyy="0.0" iyz="0.0" izz="0.0"/>
      </inertial>
    </link>

    <!-- joint 4-1: Outer Roll shaft -->
    <joint name="${prefix}outer_roll_shaft_joint" type="fixed">
      <parent link="${prefix}tool_wrist_link"/>
      <child link="${prefix}tool_wrist_shaft_link"/>
      <axis xyz="0 0 1"/>
      <origin rpy="0 0 0" xyz="0 0 0.0091"/>
    </joint>

    <!-- link 4-1: tool_wrist_shaft_link /finger2 -->
    <link name="${prefix}tool_wrist_shaft_link">
      <visual>
        <origin rpy="1.5708 0 0" xyz="0 0.00401 0"/>
        <geometry>
          <mesh filename="package://dvrk_model/meshes/psm/tool_wrist_shaft_link.dae"/> 
        </geometry>
      </visual>
      <inertial>
        <mass value="0.000337"/>
        <inertia ixx="0.0" ixy="0.0" ixz="0.0" iyy="0.0" iyz="0.0" izz="0.0"/>
      </inertial>
    </link>

    <!-- joint 5: Outer wrist pitch joint -->
    <joint name="${prefix}outer_wrist_pitch_joint" type="revolute">
      <parent link="${prefix}tool_wrist_shaft_link"/>
      <child link="${prefix}tool_wrist_sca_link"/>
      <axis xyz="0 0 1"/>
      <origin rpy="-1.5708 -1.5708 0" xyz="0 0 0"/>
      <limit lower="-1.5707" upper="1.5707" velocity=".4" effort="1000"/>
    </joint>

    <!-- link 5: tool_wrist_sca_link /finger3 -->
    <link name="${prefix}tool_wrist_sca_link">
      <visual>
        <!-- <origin rpy="0 3.1416 0" xyz="0 0 0"/> -->
        <origin rpy="1.5708 3.1416 0" xyz="0.0051 0.0032 0"/>
        <geometry>
          <mesh filename="package://dvrk_model/meshes/psm/tool_wrist_sca_link.dae"/> 
        </geometry>
      </visual>
      <inertial>
        <mass value="0.000164"/>
        <inertia ixx="0.0" ixy="0.0" ixz="0.0" iyy="0.0" iyz="0.0" izz="0.0"/>
      </inertial>
    </link>

    <!-- joint 5-2: Outer wristyaw joint -->
    <joint name="${prefix}outer_wrist_yaw_joint" type="revolute">
      <parent link="${prefix}tool_wrist_sca_link"/>
      <child link="${prefix}tool_wrist_sca_shaft_link"/>
      <axis xyz="0 0 1"/>
      <origin rpy="-1.5708 -1.5708 0" xyz="0.0089 0 0"/>
      <!-- +/- 80 deg -->
      <limit lower="-1.3963" upper="1.3963" velocity=".4" effort="1000"/>
    </joint>

    <!-- link 5-2: tool_wrist_sca_shaft_link -->
    <link name="${prefix}tool_wrist_sca_shaft_link">
      <visual>
        <origin rpy="0 0 0" xyz="0 0 -0.0025"/>
        <geometry>
          <mesh filename="package://dvrk_model/meshes/psm/tool_wrist_sca_shaft_link.dae"/> 
        </geometry>
      </visual>
      <inertial>
        <mass value="1"/>
        <inertia ixx="1.0" ixy="0.0" ixz="0.0" iyy="1.0" iyz="0.0" izz="1.0"/>
      </inertial>
    </link>
    
    <!-- joint 6-1: Outer open angle 1  -->
    <joint name="${prefix}outer_wrist_open_angle_joint_1" type="revolute">
      <parent link="${prefix}tool_wrist_sca_shaft_link"/>
      <child link="${prefix}tool_wrist_sca_ee_link_1"/>
      <axis xyz="0 0 1"/>
      <origin rpy="0 0 0" xyz="0 0 0"/>
      <!-- <origin rpy="-1.5708 -1.5708 0" xyz="0 0 0"/> -->
      <limit lower="0" upper="1.5707" velocity=".4" effort="1000"/>
    </joint>

    <!-- link 6-1: Outer open angle link 1 -->
    <link name="${prefix}tool_wrist_sca_ee_link_1">
      <visual>
        <origin rpy="0 0 0" xyz="0 0 0"/>
        <geometry>
          <mesh filename="package://dvrk_model/meshes/psm/tool_wrist_sca_link_2.dae"/>
        </geometry>
      </visual>
      <inertial>
        <mass value="1"/>
        <inertia ixx="1.0" ixy="0.0" ixz="0.0" iyy="1.0" iyz="0.0" izz="1.0"/>
      </inertial>
    </link>

    <!-- joint 6-2: Outer open angle 2   -->
    <joint name="${prefix}outer_wrist_open_angle_joint_2" type="revolute">
      <parent link="${prefix}tool_wrist_sca_shaft_link"/>
      <child link="${prefix}tool_wrist_sca_ee_link_2"/>
      <axis xyz="0 0 1"/>
      <origin rpy="0 0 0" xyz="0 0 0"/>
      <limit lower="-1.5707" upper="1.5707" velocity=".4" effort="1000"/>
      <mimic joint="${prefix}outer_wrist_open_angle_joint_1" multiplier="-1"/>
    </joint>

    <!-- link 6-2: Outer open angle link 2 -->
    <link name="${prefix}tool_wrist_sca_ee_link_2">
      <visual>
        <origin rpy="0 3.1516 0" xyz="0 0 0"/>
        <geometry>
          <mesh filename="package://dvrk_model/meshes/psm/tool_wrist_sca_link_2.dae"/>
        </geometry>
      </visual>
      <inertial>
        <mass value="1"/>
        <inertia ixx="1.0" ixy="0.0" ixz="0.0" iyy="1.0" iyz="0.0" izz="1.0"/>
      </inertial>
    </link>

    <transmission name="tran1">
      <type>transmission_interface/SimpleTransmission</type>
      <joint name="${prefix}outer_yaw_joint"/>
      <actuator name="motor1">
        <hardwareInterface>EffortJointInterface</hardwareInterface>
        <mechanicalReduction>1</mechanicalReduction>
      </actuator>
    </transmission>
    <transmission name="tran2">
      <type>transmission_interface/SimpleTransmission</type>
      <joint name="${prefix}outer_pitch_joint_1"/>
      <actuator name="motor2">
        <hardwareInterface>EffortJointInterface</hardwareInterface>
        <mechanicalReduction>1</mechanicalReduction>
      </actuator>
    </transmission>
    <transmission name="tran3">
      <type>transmission_interface/SimpleTransmission</type>
      <joint name="${prefix}outer_insertion_joint"/>
      <actuator name="motor3">
        <hardwareInterface>EffortJointInterface</hardwareInterface>
        <mechanicalReduction>1</mechanicalReduction>
      </actuator>
    </transmission>
    <transmission name="tran4">
      <type>transmission_interface/SimpleTransmission</type>
      <joint name="${prefix}outer_roll_joint"/>
      <actuator name="motor4">
        <hardwareInterface>EffortJointInterface</hardwareInterface>
        <mechanicalReduction>1</mechanicalReduction>
      </actuator>
    </transmission>
    <transmission name="tran5">
      <type>transmission_interface/SimpleTransmission</type>
      <joint name="${prefix}outer_wrist_pitch_joint"/>
      <actuator name="motor5">
        <hardwareInterface>EffortJointInterface</hardwareInterface>
        <mechanicalReduction>1</mechanicalReduction>
      </actuator>
    </transmission>
    <transmission name="tran6">
      <type>transmission_interface/SimpleTransmission</type>
      <joint name="${prefix}outer_wrist_yaw_joint"/>
      <actuator name="motor6">
        <hardwareInterface>EffortJointInterface</hardwareInterface>
        <mechanicalReduction>1</mechanicalReduction>
      </actuator>
    </transmission>
    <transmission name="tran7">
      <type>transmission_interface/SimpleTransmission</type>
      <joint name="${prefix}outer_wrist_open_angle_joint_1"/>
      <actuator name="motor7">
        <hardwareInterface>EffortJointInterface</hardwareInterface>
        <mechanicalReduction>1</mechanicalReduction>
      </actuator>
    </transmission>

    <gazebo>
      <plugin name="gazebo_ros_control" filename="libgazebo_ros_control.so">
        <robotNamespace>/dvrk_psm</robotNamespace>
      </plugin>
    </gazebo>

  </xacro:macro>
  
</robot>
